[2024-11-12T14:46:16.556+0000] {local_task_job_runner.py:120} INFO - ::group::Pre task execution logs
[2024-11-12T14:46:16.572+0000] {taskinstance.py:2073} INFO - Dependencies all met for dep_context=non-requeueable deps ti=<TaskInstance: ETL_DAG.extract scheduled__2024-11-11T00:00:00+00:00 [queued]>
[2024-11-12T14:46:16.578+0000] {taskinstance.py:2073} INFO - Dependencies all met for dep_context=requeueable deps ti=<TaskInstance: ETL_DAG.extract scheduled__2024-11-11T00:00:00+00:00 [queued]>
[2024-11-12T14:46:16.578+0000] {taskinstance.py:2303} INFO - Starting attempt 1 of 2
[2024-11-12T14:46:16.588+0000] {taskinstance.py:2327} INFO - Executing <Task(PythonOperator): extract> on 2024-11-11 00:00:00+00:00
[2024-11-12T14:46:16.593+0000] {warnings.py:110} WARNING - /home/***/.local/lib/python3.12/site-packages/***/task/task_runner/standard_task_runner.py:61: DeprecationWarning: This process (pid=57) is multi-threaded, use of fork() may lead to deadlocks in the child.
  pid = os.fork()

[2024-11-12T14:46:16.594+0000] {standard_task_runner.py:90} INFO - Running: ['***', 'tasks', 'run', 'ETL_DAG', 'extract', 'scheduled__2024-11-11T00:00:00+00:00', '--job-id', '60', '--raw', '--subdir', 'DAGS_FOLDER/DAG.py', '--cfg-path', '/tmp/tmpj2rs_zn2']
[2024-11-12T14:46:16.595+0000] {standard_task_runner.py:63} INFO - Started process 59 to run task
[2024-11-12T14:46:16.595+0000] {standard_task_runner.py:91} INFO - Job 60: Subtask extract
[2024-11-12T14:46:16.631+0000] {task_command.py:426} INFO - Running <TaskInstance: ETL_DAG.extract scheduled__2024-11-11T00:00:00+00:00 [running]> on host 8143f6d80b45
[2024-11-12T14:46:16.700+0000] {taskinstance.py:2644} INFO - Exporting env vars: AIRFLOW_CTX_DAG_OWNER='***' AIRFLOW_CTX_DAG_ID='ETL_DAG' AIRFLOW_CTX_TASK_ID='extract' AIRFLOW_CTX_EXECUTION_DATE='2024-11-11T00:00:00+00:00' AIRFLOW_CTX_TRY_NUMBER='1' AIRFLOW_CTX_DAG_RUN_ID='scheduled__2024-11-11T00:00:00+00:00'
[2024-11-12T14:46:16.701+0000] {taskinstance.py:430} INFO - ::endgroup::
[2024-11-12T14:46:17.816+0000] {taskinstance.py:441} INFO - ::group::Post task execution logs
[2024-11-12T14:46:17.816+0000] {taskinstance.py:2890} ERROR - Task failed with exception
Traceback (most recent call last):
  File "/home/airflow/.local/lib/python3.12/site-packages/airflow/models/taskinstance.py", line 465, in _execute_task
    result = _execute_callable(context=context, **execute_callable_kwargs)
             ^^^^^^^^^^^^^^^^^^^^^^^^^^^^^^^^^^^^^^^^^^^^^^^^^^^^^^^^^^^^^
  File "/home/airflow/.local/lib/python3.12/site-packages/airflow/models/taskinstance.py", line 432, in _execute_callable
    return execute_callable(context=context, **execute_callable_kwargs)
           ^^^^^^^^^^^^^^^^^^^^^^^^^^^^^^^^^^^^^^^^^^^^^^^^^^^^^^^^^^^^
  File "/home/airflow/.local/lib/python3.12/site-packages/airflow/models/baseoperator.py", line 400, in wrapper
    return func(self, *args, **kwargs)
           ^^^^^^^^^^^^^^^^^^^^^^^^^^^
  File "/home/airflow/.local/lib/python3.12/site-packages/airflow/operators/python.py", line 235, in execute
    return_value = self.execute_callable()
                   ^^^^^^^^^^^^^^^^^^^^^^^
  File "/home/airflow/.local/lib/python3.12/site-packages/airflow/operators/python.py", line 252, in execute_callable
    return self.python_callable(*self.op_args, **self.op_kwargs)
           ^^^^^^^^^^^^^^^^^^^^^^^^^^^^^^^^^^^^^^^^^^^^^^^^^^^^^
  File "/opt/airflow/dags/DAG.py", line 34, in extract
    df = pd.read_parquet('https://github.com/jgutierrezladino/Feastly/blob/docker-airflow/metadatos2.parquet')
         ^^^^^^^^^^^^^^^^^^^^^^^^^^^^^^^^^^^^^^^^^^^^^^^^^^^^^^^^^^^^^^^^^^^^^^^^^^^^^^^^^^^^^^^^^^^^^^^^^^^^^
  File "/home/airflow/.local/lib/python3.12/site-packages/pandas/io/parquet.py", line 670, in read_parquet
    return impl.read(
           ^^^^^^^^^^
  File "/home/airflow/.local/lib/python3.12/site-packages/pandas/io/parquet.py", line 272, in read
    pa_table = self.api.parquet.read_table(
               ^^^^^^^^^^^^^^^^^^^^^^^^^^^^
  File "/home/airflow/.local/lib/python3.12/site-packages/pyarrow/parquet/core.py", line 1776, in read_table
    dataset = ParquetDataset(
              ^^^^^^^^^^^^^^^
  File "/home/airflow/.local/lib/python3.12/site-packages/pyarrow/parquet/core.py", line 1343, in __init__
    [fragment], schema=schema or fragment.physical_schema,
                                 ^^^^^^^^^^^^^^^^^^^^^^^^
  File "pyarrow/_dataset.pyx", line 1367, in pyarrow._dataset.Fragment.physical_schema.__get__
  File "pyarrow/error.pxi", line 154, in pyarrow.lib.pyarrow_internal_check_status
  File "pyarrow/error.pxi", line 91, in pyarrow.lib.check_status
pyarrow.lib.ArrowInvalid: Could not open Parquet input source '<Buffer>': Parquet magic bytes not found in footer. Either the file is corrupted or this is not a parquet file.
[2024-11-12T14:46:17.826+0000] {taskinstance.py:1205} INFO - Marking task as UP_FOR_RETRY. dag_id=ETL_DAG, task_id=extract, execution_date=20241111T000000, start_date=20241112T144616, end_date=20241112T144617
[2024-11-12T14:46:17.835+0000] {standard_task_runner.py:110} ERROR - Failed to execute job 60 for task extract (Could not open Parquet input source '<Buffer>': Parquet magic bytes not found in footer. Either the file is corrupted or this is not a parquet file.; 59)
[2024-11-12T14:46:17.852+0000] {local_task_job_runner.py:240} INFO - Task exited with return code 1
[2024-11-12T14:46:17.869+0000] {taskinstance.py:3482} INFO - 0 downstream tasks scheduled from follow-on schedule check
[2024-11-12T14:46:17.872+0000] {local_task_job_runner.py:222} INFO - ::endgroup::
