[2024-11-15T14:26:08.420+0000] {task_context_logger.py:104} WARNING - Marking task instance <TaskInstance: ETL_DAG.extract manual__2024-11-14T20:29:21.893710+00:00 [queued]> stuck in queued as failed. If the task instance has available retries, it will be retried.
[2024-11-15T14:26:08.578+0000] {task_context_logger.py:104} ERROR - Executor reports task instance <TaskInstance: ETL_DAG.extract manual__2024-11-14T20:29:21.893710+00:00 [queued]> finished (failed) although the task says it's queued. (Info: None) Was the task killed externally?
