[2024-11-07T21:21:51.171+0000] {task_context_logger.py:104} ERROR - Executor reports task instance <TaskInstance: MI_DAG.second_task scheduled__2024-11-05T09:00:00+00:00 [queued]> finished (failed) although the task says it's queued. (Info: None) Was the task killed externally?
